<?xml version="1.0" ?>
<!-- =================================================================================== -->
<!-- |    This document was autogenerated by xacro from lwr_robot.xacro                | -->
<!-- |    EDITING THIS FILE BY HAND IS NOT RECOMMENDED                                 | -->
<!-- =================================================================================== -->
<robot name="LWR" xmlns:controller="http://playerstage.sourceforge.net/gazebo/xmlschema/#controller" xmlns:interface="http://playerstage.sourceforge.net/gazebo/xmlschema/#interface" xmlns:sensor="http://playerstage.sourceforge.net/gazebo/xmlschema/#sensor" xmlns:xacro="http://ros.org/wiki/xacro">
  <!-- Import all Gazebo-customization elements, including Gazebo colors -->
  <gazebo>
    <plugin filename="libgazebo_ros_control.so" name="gazebo_ros_control">
      <robotNamespace>/lwr</robotNamespace>
    </plugin>
  </gazebo>
  <!-- Inserts the Kuka here with a specified name and direction ... -->
  <joint name="world_lwr_arm_base_joint" type="fixed">
    <origin rpy="0 0 0" xyz="0 0 0"/>
    <parent link="world"/>
    <child link="calib_lwr_arm_base_link"/>
  </joint>
  <link name="calib_lwr_arm_base_link">
    <inertial>
      <mass value="2.0"/>
      <origin rpy="0 0 0" xyz="0 0 0.055"/>
      <inertia ixx="0.00381666666667" ixy="0" ixz="0" iyy="0.0036" iyz="0" izz="0.00381666666667"/>
    </inertial>
    <visual>
      <origin rpy="0 0 0" xyz="0 0 0"/>
      <geometry>
        <mesh filename="package://lwr_description/meshes/meshes_arm/arm_base.dae"/>
      </geometry>
      <material name="Orange"/>
    </visual>
    <collision>
      <origin rpy="0 0 0" xyz="0 0 0"/>
      <geometry>
        <mesh filename="package://lwr_description/meshes/meshes_arm/convex/arm_base_convex.stl"/>
      </geometry>
    </collision>
  </link>
  <joint name="lwr_arm_0_joint" type="revolute">
    <origin rpy="0 0 0" xyz="0 0 0.11"/>
    <axis xyz="0 0 1"/>
    <limit effort="204" lower="-2.96705972839" upper="2.96705972839" velocity="1.91986217719"/>
    <dynamics damping="2" friction="0.1"/>
    <parent link="calib_lwr_arm_base_link"/>
    <child link="lwr_arm_1_link"/>
  </joint>
  <link name="lwr_arm_1_link">
    <inertial>
      <mass value="2.0"/>
      <origin rpy="0 0 0" xyz="0 0.05 0.130"/>
      <inertia ixx="0.0136666666667" ixy="0" ixz="0" iyy="0.0118666666667" iyz="0" izz="0.003"/>
    </inertial>
    <visual>
      <origin rpy="0 0 3.14159265359" xyz="0 0 0"/>
      <geometry>
        <mesh filename="package://lwr_description/meshes/meshes_arm/arm_segment_a.dae"/>
      </geometry>
      <material name="Orange"/>
    </visual>
    <collision>
      <origin rpy="0 0 3.14159265359" xyz="0 0 0"/>
      <geometry>
        <mesh filename="package://lwr_description/meshes/meshes_arm/convex/arm_segment_a_convex.stl"/>
      </geometry>
    </collision>
  </link>
  <joint name="lwr_arm_1_joint" type="revolute">
    <origin rpy="0 0 0" xyz="0 0 0.20"/>
    <axis xyz="0 -1 0"/>
    <limit effort="306" lower="-1.57079632679" upper="1.57079632679" velocity="1.91986217719"/>
    <safety_controller k_position="100" k_velocity="2" soft_lower_limit="-2.05948851735" soft_upper_limit="2.05948851735"/>
    <dynamics damping="2" friction="0.1"/>
    <parent link="lwr_arm_1_link"/>
    <child link="lwr_arm_2_link"/>
  </joint>
  <link name="lwr_arm_2_link">
    <inertial>
      <mass value="2.0"/>
      <origin rpy="0 0 0" xyz="0 -0.05 0.07"/>
      <inertia ixx="0.0136666666667" ixy="0" ixz="0" iyy="0.0118666666667" iyz="0" izz="0.003"/>
    </inertial>
    <visual>
      <origin rpy="3.14159265359 0 3.14159265359" xyz="0 0 0.2"/>
      <geometry>
        <mesh filename="package://lwr_description/meshes/meshes_arm/arm_segment_b.dae"/>
      </geometry>
      <material name="Orange"/>
    </visual>
    <collision>
      <origin rpy="3.14159265359 0 3.14159265359" xyz="0 0 0.2"/>
      <geometry>
        <mesh filename="package://lwr_description/meshes/meshes_arm/convex/arm_segment_b_convex.stl"/>
      </geometry>
    </collision>
  </link>
  <joint name="lwr_arm_2_joint" type="revolute">
    <origin rpy="0 0 0" xyz="0 0 0.20"/>
    <axis xyz="0 0 1"/>
    <limit effort="204" lower="-2.96705972839" upper="2.96705972839" velocity="2.26892802759"/>
    <dynamics damping="2" friction="0.1"/>
    <parent link="lwr_arm_2_link"/>
    <child link="lwr_arm_3_link"/>
  </joint>
  <link name="lwr_arm_3_link">
    <inertial>
      <mass value="2.0"/>
      <origin rpy="0 0 0" xyz="0 -0.06 0.130"/>
      <inertia ixx="0.0136666666667" ixy="0" ixz="0" iyy="0.0118666666667" iyz="0" izz="0.003"/>
    </inertial>
    <visual>
      <origin rpy="0 0 0" xyz="0 0 0"/>
      <geometry>
        <mesh filename="package://lwr_description/meshes/meshes_arm/arm_segment_a.dae"/>
      </geometry>
      <material name="Orange"/>
    </visual>
    <collision>
      <origin rpy="0 0 0" xyz="0 0 0"/>
      <geometry>
        <mesh filename="package://lwr_description/meshes/meshes_arm/convex/arm_segment_a_convex.stl"/>
      </geometry>
    </collision>
  </link>
  <joint name="lwr_arm_3_joint" type="revolute">
    <origin rpy="0 0 0" xyz="0 0 0.20"/>
    <axis xyz="0 1 0"/>
    <limit effort="306" lower="-2.09439510239" upper="2.09439510239" velocity="2.26892802759"/>
    <safety_controller k_position="100" k_velocity="2" soft_lower_limit="-2.05948851735" soft_upper_limit="2.05948851735"/>
    <dynamics damping="2" friction="0.1"/>
    <parent link="lwr_arm_3_link"/>
    <child link="lwr_arm_4_link"/>
  </joint>
  <link name="lwr_arm_4_link">
    <inertial>
      <mass value="2.0"/>
      <origin rpy="0 0 0" xyz="0 0.06 0.07"/>
      <inertia ixx="0.0136666666667" ixy="0" ixz="0" iyy="0.0118666666667" iyz="0" izz="0.003"/>
    </inertial>
    <visual>
      <origin rpy="0 3.14159265359 3.14159265359" xyz="0 0 0.2"/>
      <geometry>
        <mesh filename="package://lwr_description/meshes/meshes_arm/arm_segment_b.dae"/>
      </geometry>
      <material name="Orange"/>
    </visual>
    <collision>
      <origin rpy="0 3.14159265359 3.14159265359" xyz="0 0 0.2"/>
      <geometry>
        <mesh filename="package://lwr_description/meshes/meshes_arm/convex/arm_segment_b_convex.stl"/>
      </geometry>
    </collision>
  </link>
  <joint name="lwr_arm_4_joint" type="revolute">
    <origin rpy="0 0 0" xyz="0 0 0.20"/>
    <axis xyz="0 0 1"/>
    <limit effort="204" lower="-2.96705972839" upper="2.96705972839" velocity="2.26892802759"/>
    <safety_controller k_position="100" k_velocity="2" soft_lower_limit="-2.93215314335" soft_upper_limit="2.93215314335"/>
    <dynamics damping="2" friction="0.1"/>
    <parent link="lwr_arm_4_link"/>
    <child link="lwr_arm_5_link"/>
  </joint>
  <link name="lwr_arm_5_link">
    <inertial>
      <mass value="2.0"/>
      <origin rpy="0 0 0" xyz="0 0 0.124"/>
      <inertia ixx="0.0126506666667" ixy="0" ixz="0" iyy="0.0108506666667" iyz="0" izz="0.003"/>
    </inertial>
    <visual>
      <origin rpy="0 0 3.14159265359" xyz="0 0 0"/>
      <geometry name="lwr_arm_5_geom">
        <mesh filename="package://lwr_description/meshes/meshes_arm/arm_segment_last.dae"/>
      </geometry>
      <material name="Orange"/>
    </visual>
    <collision>
      <origin rpy="0 0 3.14159265359" xyz="0 0 0"/>
      <geometry>
        <mesh filename="package://lwr_description/meshes/meshes_arm/convex/arm_segment_last_convex.stl"/>
      </geometry>
    </collision>
  </link>
  <joint name="lwr_arm_5_joint" type="revolute">
    <origin rpy="0 0 0" xyz="0 0 0.19"/>
    <axis xyz="0 -1 0"/>
    <limit effort="306" lower="-2.09439510239" upper="2.09439510239" velocity="3.14159265359"/>
    <safety_controller k_position="100" k_velocity="2" soft_lower_limit="-2.05948851735" soft_upper_limit="2.05948851735"/>
    <dynamics damping="2" friction="0.1"/>
    <parent link="lwr_arm_5_link"/>
    <child link="lwr_arm_6_link"/>
  </joint>
  <link name="lwr_arm_6_link">
    <inertial>
      <mass value="2.0"/>
      <origin rpy="0 0 0" xyz="0 0 0.0625"/>
      <inertia ixx="0.00520833333333" ixy="0" ixz="0" iyy="0.00520833333333" iyz="0" izz="0.00520833333333"/>
    </inertial>
    <visual>
      <origin rpy="0 0 3.14159265359" xyz="0 0 0"/>
      <geometry>
        <mesh filename="package://lwr_description/meshes/meshes_arm/arm_wrist.dae"/>
      </geometry>
      <material name="Grey"/>
    </visual>
    <collision>
      <origin rpy="0 0 3.14159265359" xyz="0 0 0"/>
      <geometry>
        <mesh filename="package://lwr_description/meshes/meshes_arm/convex/arm_wrist_convex.stl"/>
      </geometry>
    </collision>
  </link>
  <joint name="lwr_arm_6_joint" type="revolute">
    <origin rpy="0 0 0" xyz="0 0 0.078"/>
    <axis xyz="0 0 1"/>
    <limit effort="204" lower="-2.96705972839" upper="2.96705972839" velocity="3.14159265359"/>
    <safety_controller k_position="100" k_velocity="2" soft_lower_limit="-2.93215314335" soft_upper_limit="2.93215314335"/>
    <dynamics damping="2" friction="0.1"/>
    <parent link="lwr_arm_6_link"/>
    <child link="lwr_arm_7_link"/>
  </joint>
  <link name="lwr_arm_7_link">
    <inertial>
      <mass value="2.0"/>
      <origin xyz="0 0 0"/>
      <inertia ixx="0.0133333333333" ixy="0" ixz="0" iyy="0.0133333333333" iyz="0" izz="0.0133333333333"/>
    </inertial>
    <visual>
      <origin rpy="0 0 2.35619449019" xyz="0 0 0"/>
      <geometry>
        <mesh filename="package://lwr_description/meshes/meshes_arm/arm_flanche.dae"/>
      </geometry>
      <material name="Grey"/>
    </visual>
    <collision>
      <origin rpy="0 0 2.35619449019" xyz="0 0 0"/>
      <geometry>
        <mesh filename="package://lwr_description/meshes/meshes_arm/convex/arm_flanche_convex.stl"/>
      </geometry>
    </collision>
  </link>
  <transmission name="lwr_arm_0_trans">
    <type>transmission_interface/SimpleTransmission</type>
    <joint name="lwr_arm_0_joint">
      <hardwareInterface>EffortJointInterface</hardwareInterface>
    </joint>
    <actuator name="lwr_motor_0">
      <mechanicalReduction>1</mechanicalReduction>
    </actuator>
  </transmission>
  <transmission name="lwr_arm_1_trans">
    <type>transmission_interface/SimpleTransmission</type>
    <joint name="lwr_arm_1_joint">
      <hardwareInterface>EffortJointInterface</hardwareInterface>
    </joint>
    <actuator name="lwr_motor_1">
      <mechanicalReduction>1</mechanicalReduction>
    </actuator>
  </transmission>
  <transmission name="lwr_arm_2_trans">
    <type>transmission_interface/SimpleTransmission</type>
    <joint name="lwr_arm_2_joint">
      <hardwareInterface>EffortJointInterface</hardwareInterface>
    </joint>
    <actuator name="lwr_motor_2">
      <mechanicalReduction>1</mechanicalReduction>
    </actuator>
  </transmission>
  <transmission name="lwr_arm_3_trans">
    <type>transmission_interface/SimpleTransmission</type>
    <joint name="lwr_arm_3_joint">
      <hardwareInterface>EffortJointInterface</hardwareInterface>
    </joint>
    <actuator name="lwr_motor_3">
      <mechanicalReduction>1</mechanicalReduction>
    </actuator>
  </transmission>
  <transmission name="lwr_arm_4_trans">
    <type>transmission_interface/SimpleTransmission</type>
    <joint name="lwr_arm_4_joint">
      <hardwareInterface>EffortJointInterface</hardwareInterface>
    </joint>
    <actuator name="lwr_motor_4">
      <mechanicalReduction>1</mechanicalReduction>
    </actuator>
  </transmission>
  <transmission name="lwr_arm_5_trans">
    <type>transmission_interface/SimpleTransmission</type>
    <joint name="lwr_arm_5_joint">
      <hardwareInterface>EffortJointInterface</hardwareInterface>
    </joint>
    <actuator name="lwr_motor_5">
      <mechanicalReduction>1</mechanicalReduction>
    </actuator>
  </transmission>
  <transmission name="lwr_arm_6_trans">
    <type>transmission_interface/SimpleTransmission</type>
    <joint name="lwr_arm_6_joint">
      <hardwareInterface>EffortJointInterface</hardwareInterface>
    </joint>
    <actuator name="lwr_motor_6">
      <mechanicalReduction>1</mechanicalReduction>
    </actuator>
  </transmission>
  <gazebo reference="lwr_arm_0_joint">
    <provideFeedback>true</provideFeedback>
    <mu1>0.05</mu1>
    <mu2>0.05</mu2>
    <kp>400000.0</kp>
  </gazebo>
  <gazebo reference="lwr_arm_1_joint">
    <provideFeedback>true</provideFeedback>
    <mu1>0.05</mu1>
    <mu2>0.05</mu2>
    <kp>400000.0</kp>
  </gazebo>
  <gazebo reference="lwr_arm_2_joint">
    <provideFeedback>true</provideFeedback>
    <mu1>0.05</mu1>
    <mu2>0.05</mu2>
    <kp>400000.0</kp>
  </gazebo>
  <gazebo reference="lwr_arm_3_joint">
    <provideFeedback>true</provideFeedback>
    <mu1>0.05</mu1>
    <mu2>0.05</mu2>
    <kp>400000.0</kp>
  </gazebo>
  <gazebo reference="lwr_arm_4_joint">
    <provideFeedback>true</provideFeedback>
    <mu1>0.05</mu1>
    <mu2>0.05</mu2>
    <kp>400000.0</kp>
  </gazebo>
  <gazebo reference="lwr_arm_5_joint">
    <provideFeedback>true</provideFeedback>
    <mu1>0.05</mu1>
    <mu2>0.05</mu2>
    <kp>400000.0</kp>
  </gazebo>
  <gazebo reference="lwr_arm_6_joint">
    <provideFeedback>true</provideFeedback>
    <mu1>0.05</mu1>
    <mu2>0.05</mu2>
    <kp>400000.0</kp>
  </gazebo>
  <gazebo reference="lwr_arm_7_joint">
    <provideFeedback>true</provideFeedback>
    <mu1>0.05</mu1>
    <mu2>0.05</mu2>
    <kp>400000.0</kp>
  </gazebo>
  <gazebo reference="calib_lwr_arm_base_link">
    <mu1>0.05</mu1>
    <mu2>0.05</mu2>
    <kp>400000.0</kp>
    <selfCollide>true</selfCollide>
  </gazebo>
  <gazebo reference="lwr_arm_2_link">
    <mu1>0.05</mu1>
    <mu2>0.05</mu2>
    <kp>400000.0</kp>
    <selfCollide>true</selfCollide>
  </gazebo>
  <gazebo reference="lwr_arm_3_link">
    <mu1>0.05</mu1>
    <mu2>0.05</mu2>
    <kp>400000.0</kp>
    <selfCollide>true</selfCollide>
  </gazebo>
  <gazebo reference="lwr_arm_4_link">
    <mu1>0.05</mu1>
    <mu2>0.05</mu2>
    <kp>400000.0</kp>
    <selfCollide>true</selfCollide>
  </gazebo>
  <gazebo reference="lwr_arm_5_link">
    <mu1>0.05</mu1>
    <mu2>0.05</mu2>
    <kp>400000.0</kp>
    <selfCollide>true</selfCollide>
  </gazebo>
  <gazebo reference="lwr_arm_6_link">
    <mu1>0.05</mu1>
    <mu2>0.05</mu2>
    <kp>400000.0</kp>
    <selfCollide>true</selfCollide>
  </gazebo>
  <gazebo reference="lwr_arm_7_link">
    <mu1>0.05</mu1>
    <mu2>0.05</mu2>
    <kp>400000.0</kp>
    <selfCollide>true</selfCollide>
  </gazebo>
  <link name="world"/>
</robot>

